<?xml version="1.0"?>
<robot name="system">

  <link name="base_link"> 
    <visual>
      <geometry>
        <cylinder length="0.05" radius="0.6"/>
      </geometry>
      <material name="blue">
        <color rgba="0 0 1 1"/>
      </material>
    </visual>
  </link>

  <link name="ball">
    <visual>
      <geometry>
        <sphere radius="0.05"/>
      </geometry>
      <material name="red">
        <color rgba="1 0 0 1"/>
      </material>
    </visual>
  </link>

  <joint name="joint1" type="revolute">
    <parent link="base_link"/> 
    <child link="ball"/>
    <axies xyz="0 0 0"/>
    <origin xyz="0 0 0.05" rpy="0 0 0"/>
    <limit lower="-3.1416" upper="3.1416" effort="1000" velocity="0.5"/>
  </joint>

</robot>
